## Error 实例对象

**`JS`解析或运行时，一旦发生错误，引擎就会抛出一个错误对象。`JS`原生提供`Error`构造函数，所有抛出的错误都是这个构造函数的实例。**

```
const err = new Error('出错了');
err.message; // '出错了'
```

**上面代码调用`Error`构造函数，生成一个实例对象`err`。`Error`构造函数接受一个参数，表示错误提示，可以从实例的`message`属性读到这个参数。抛出`Error`实例对象后，整个程序就中断在发生错误的地方，不再往下执行。**

**`Error`实例对象必须有`message`属性（表示出错时的提示信息），同时还提供`name`（错误的名称）和`stack`（错误的堆栈）。**

- Message：错误提示信息
- name：错误名称(非标准属性)
- stack：错误的堆栈(非标准属性)

**使用`name`和`message`这两个属性，可以对发生什么错误有大概的了解。**

```
if (error.name) {
	console.log(`${error.name}: ${error.message}`);
}
```

**`stack`属性用来查看错误发生时的堆栈。**

```
function throwit() {
	throw new Error('zhangjing');
}

function catchit() {
	try {
		throwit();
	} catch (e) {
		console.log(e.stack);
	}
}

catchit();
```

**错误堆栈的最内层是`throwit`函数，然后是`catchit`函数，最后是函数的运行环境。**

## 原生错误类型

**`Error`实例对象是最一般的错误类型，在它基础上，JS还定义了其他6种错误对象，即存在`Error`的6个派生对象。**

### SyntaxError 对象

**<font color="#c7254e">`SyntaxError`</font>对象是解析代码时发生的语法错误。**

```
// 变量名错误
var 1a;
// Uncaught SyntaxError: Invalid or unexpected token

// 缺少括号
console.log 'hello');
// Uncaught SyntaxError: Unexpected string
```

### ReferenceError 对象

**<font color="#c7254e">`ReferenceError`</font>对象是引用一个不存在的变量时发生的错误。**

```
// 使用一个不存在的变量
console.log(dasda);
// Uncaught ReferenceError: dasda is not defined
```

**另一种触发场景：将一个值分配给无法分配的对象，比如对函数的运行结果或者`this`赋值。**

```
// 等号左侧不是变量
console.log() = 11;

// this对象不能手动赋值
this = 1;
```

### RangeError 对象

**<font color="#c7254e">`RangeError`</font>对象是一个值超出有效范围时发生的错误。主要有几种情况：1.数组长度为负数；2.<font color="#c7254e">`Number`</font>对象的方法参数超出范围，以及函数堆栈超过最大值。**

```
// 数组长度不能为负数
new Array(-11)
// Uncaught RangeError: Invalid array length
```

### TypeError 对象

**<font color="#c7254e">`TypeError`</font>对象是变量或参数不是预期类型时发生的错误。如对字符串、布尔值、数值等原始类型的值使用<font color="#c7254e">`new`</font>命令，就会抛出这种错误，因为<font color="#c7254e">`new`</font>命令的参数应该是一个构造函数。**

```
new 123
// Uncaught TypeError: number is not a func

// 调用对象不存在的方法，也会抛出TypeError错误
var obj = {};
obj.unknowMethod();
// Uncaught TypeError: obj.unknownMethod is not a function
```

### URIError 对象

**`URIError`对象是URI相关函数的参数不正确时抛出的错误，主要涉及<font color="#c7254e">`encodeURI()`</font>、<font color="#c7254e">`decodeURI()`</font>、<font color="#c7254e">`encodeURIComponent()`</font>、<font color="#c7254e">`decodeURIComponent()`</font>、<font color="#c7254e">`escape()`</font>、<font color="#c7254e">`unescape()`</font>这六个函数。**

```
decodeURI('%2')
```

### EvalError 对象

**`eval`函数没有被正确执行时，会抛出`EvalError`错误。**

### 总结

**上面6种派生错误，连同原始的<font color="#c7254e">`Error`</font>对象，都是构造函数。可以使用它们，手动生成错误对象的实例。这些构造函数都接受一个参数，代表错误提示信息（message）。**

```
var err1 = new Error('出错了！');
var err2 = new RangeError('出错了，变量超出有效范围！');
var err3 = new TypeError('出错了，变量类型无效！');

err1.message // "出错了！"
err2.message // "出错了，变量超出有效范围！"
err3.message // "出错了，变量类型无效！"
```

## 自定义错误

**可以自定义自己的错误对象。**

```
function UserError(message = "默认信息") {
	this.message = message;
	this.name = "UserError";
}

// 自定义一个错误对象UserError，让它继承Error对象。
UserError.prototype = new Error();
UserError.prototype.constructor = UserError;

new UserError('自定义的错误！');
// UserError {
			message: '自定义的错误！',
			name: 'UserError'
	 }
```

## throw 语句

**<font color="#c7254e">`throw`</font>语句的作用：手动中断程序执行，抛出一个错误。**

```
// throw抛出的错误就是它的参数，这里是一个Error实例。
cosnt x = -10;
if (x < 0) {
	throw new Error('x 必须为正数');
}
// Uncaught Error: x 必须为正数
```

**<font color="#c7254e">`throw`</font>也可以抛出自定义错误。**

```
function UserError(message = "默认信息") {
	this.message = message;
	this.name = 'UserError';
}

// throw抛出的是一个UserError实例
throw new UserError('出错了！');
// Uncaught UserError {message: "出错了！", name: "UserError"}
```

**<font color="#c7254e">`throw`</font>可以抛出任何类型的值。即它的参数可以是任何值。**

```
// 抛出一个字符串
throw 'Error!';

// 抛出一个数值
throw 42;

// 抛出一个布尔值
throw true;

// 抛出一个对象
throw {
	toStirng () {
		return 'Error!';
	}
}
```

**对应`JS`引擎，遇到<font color="#c7254e">`throw`</font>语句，程序就中止了。引擎会接收到<font color="#c7254e">`throw`</font>抛出的信息，可能是一个错误实例，也可能是其他类型的值。**

## try…catch 结构

**一旦发生错误，程序就中止执行了。`JS`提供了<font color="#c7254e">`try...catch`</font>结构，允许对错误进行处理，选择是否往下执行。**

```
try {
	throw new Error('出错了！')
} catch (e) {
	console.log(e);
}
console.log('continue');

// Error: 出错了！
// continue
```

**<font color="#c7254e">`try`</font>代码抛出错误，`JS`引擎立即把代码的执行转到<font color="#c7254e">`catch`</font>代码块，或者说错误被<font color="#c7254e">`catch`</font>代码块捕获了。<font color="#c7254e">`catch`</font>接受一个参数，表示<font color="#c7254e">`try`</font>代码块抛出的值。**

**若不确定某些代码是否会报错，可以把它们放在<font color="#c7254e">`try...catch`</font>代码块之中，便于进一步对错误进行处理。**

````
// 若函数f执行报错，就会进入catch代码块，对错误进行处理。
try {
	func();
} catch (e) {
	// 处理错误
}
````

**<font color="#c7254e">`catch`</font>代码块捕获错误之后，程序不会中断，会按照正常流程继续执行下去。**

```
try {
  throw "出错了";
} catch (e) {
  console.log(111);
}
console.log(222);

// 111
// 222
```

**<font color="#c7254e">`catch`</font>代码块之中，还可以再抛出错误，甚至使用嵌套的<font color="#c7254e">`try...catch`</font>结构。**

```
const n = 100;
try {
	throw n;
} catch (e) {
	if (e <= 50) {
		throw new Error("传入的值小于50");
	} else {
		throw e;
	}
}

// Uncaught 100


function ld(x){
	if (x < 10) {
		throw new Error('x小于10');
	}else if (x < 20) {
		throw new Error('x小于20');
	}else if (x < 30) {
		throw new Error('x小于30');
	}
}
// 嵌套的try...catch
try {
	ld(24)
} catch(e) {
	console.log(e);
	if(e.message == 'x小于30') {
		throw '噢噢噢噢';
	}
}
// Error: x小于30
// Uncaught 噢噢噢噢
```

**为了捕捉不同类型的错误，<font color="#c7254e">`catch`</font>代码块之中可以加入判断语句。**

```
// 封装捕捉异常错误的函数
function catchErrorFn(param) {
      try {
        if (typeof param === 'function') {
        		param()
        }
      } catch (e) {
        if (e instanceof TypeError) {
        		console.log(e.name + ": " + e.message);
        } else if (e instanceof ReferenceError) {
        		console.log(e.name + ": " + e.message);
        }
      }
}

function test(){
	console.log(wwee);
}

catchErrorFn(test); // ReferenceError: wwee is not defined
```

## finally 代码块

**`try...catch`结构允许在最后添加一个`finally`代码块，表示不管是否出现错误，都必需在最后运行的语句。**

```
function cleansUp () {
	try {
		throw new Error('出错了....');
		console.log('此行不会执行');
	} finally {
		console.log('完成清理工作');
	}
}

cleansUp();
// 完成清理工作
// Error：出错了...
```

**上面代码，由于没有`catch`语句块，所以错误没被捕获。执行`finally`代码块以后，程序就中断在错误抛出的地方。**

```
// try代码块没有发生错误，且里面还包括return语句，但是finally代码块依然会执行。注意，只有在其执行完毕后，才会显示return语句的值。

function idle(x) {
	try {
		console.log(x);
		return 'result';
	} finally {
		console.log('FINALLY');
	}
}

idle('hello');
// hello
// FINALLY
// "result"
```

```
// 注意：return语句的执行是排在finally代码之前，只是等finally代码执行完毕后才返回。return语句的count的值，是在finally代码块运行之前就获取了。

let count = 0;
function countUp () {
	try {
		return count;
	} finally {
		count++;
	}
}

countUp(); // 0
count; // 1
```

​		**`finally`代码块用法的典型场景**

```
// 首先打开一个文件，然后在try代码块中写入文件，若没发生错误，则运行finally代码块关闭文件；一旦发生错误，先使用catch代码块处理错误，再使用finally代码块关闭文件。

openFile();

try {
	writeFile(Data);
} catch (e) {
	handleError(e);
} finally {
	closeFile();
}
```

​		**`try...catch...finally`三者之间的执行顺序。**

```
// catch代码块结束执行之前，会先执行finally代码块。

function f() {
	try {
		console.log(0);
		throw 'bug';
	} catch (e) {
		console.log(1);
		return true;
		console.log(2);
	} finally {
		console.log(3);
		return false;
		console.log(4);
	}
	console.log(5);
}

var result = f();
// 0
// 1
// 3

result; // false
```

```
// catch代码块之中，触发转入finally代码块的标志，不仅有return语句，还有throw语句。

function f() {
	try {
		throw '出错了！';
	} catch(e) {
		console.log('捕捉到内部错误');
		throw e; // 这句原本会等到finally结束再执行
	} finally {
		return false; // 直接返回
	}
}

try {
	f();
} catch(e) {
	// 此处不会执行
	console.log('caught outer "bogus"')
}

// 捕捉到内部错误
```

**上面代码中，进入`catch`代码块之后，一遇到`throw`语句，就会去执行`finally`代码块，其中有`return false`语句，因此就直接返回，不再会回去执行`catch`代码块剩下的部分了。**

## 参考文章

- [错误处理机制](https://javascript.ruanyifeng.com/grammar/error.html)
- 